<robot name="th2">
	<link name="base_link">
		<visual>
      		<geometry>
        		<box size="0.12 0.13 0.01"/>
      		</geometry>
    	</visual>
	</link>
	<link name="link1">
	</link>
	<link name="link2">
	</link>
	<link name="link3">
	</link>
    <link name="link4">
    </link>

	<joint name="joint0" type="continuous">
		<parent link="base_link"/>
		<child link="link1"/>
		<origin rpy="0 0 0" xyz="0 0 0.005"/>
		<axis xyz="0 0 1" />
	</joint>

	<joint name="joint1" type="continuous">
		<parent link="link1"/>
		<child link="link2"/>
		<origin rpy="0 0 0" xyz="0 0 0.027"/>
		<axis xyz="0 1 0" />
		<limit lower="-1.3962634016" upper="1.3962634016" effort="3.1" velocity="7.0"></limit>	
	</joint>
	
	<joint name="joint2" type="revolute">
		<parent link="link2"/>
		<child link="link3"/>
		<origin rpy="0 0 0" xyz="0 0 0.4"/>
		<axis xyz="0 1 0" />
		<limit lower="-1.3962634016" upper="1.3962634016" effort="3.1" velocity="7.0"></limit>	
	</joint>

        <joint name="joint3" type="revolute">
                <parent link="link3"/>
                <child link="link4"/>
                <origin rpy="0 0 0" xyz="0 0 0.34"/>
                <axis xyz="0 1 0" />
		<limit lower="-1.3962634016" upper="1.3962634016" effort="3.1" velocity="7.0"></limit>
        </joint>
</robot>
